outputs/experiment2/results.txt
=== Experiment 2 Results ===
Config                             total_pnl          sharpe_ratio          max_drawdown    inventory_variance     transaction_costs       trade_frequency
----------------------------------------------------------------------------------------------------------------------------------------------------------
handcrafted                  270.02 ± 300.25           0.12 ± 0.14      1018.56 ± 147.99           8.69 ± 3.64           7.79 ± 4.18           0.07 ± 0.04
encoded/mlp                 -201.67 ± 167.34          -0.06 ± 0.05       729.27 ± 595.51           1.20 ± 0.98           1.37 ± 1.11           0.01 ± 0.01
encoded/cnn                  -339.09 ± 33.66          -0.10 ± 0.01        1216.44 ± 6.68           1.93 ± 0.11           2.27 ± 0.01           0.01 ± 0.00
encoded/ae                  -241.18 ± 161.22          -0.07 ± 0.05       834.71 ± 548.35           1.76 ± 1.64           1.59 ± 1.04           0.01 ± 0.01
best_bidask                   15.80 ± 268.08           0.01 ± 0.09      1024.21 ± 344.43           5.65 ± 3.87           3.60 ± 1.87           0.03 ± 0.02

--- Welch t-tests (PnL) ---
  handcrafted vs encoded/mlp: p=0.0010  ✓ significant
  handcrafted vs encoded/cnn: p=0.0002  ✓ significant
  handcrafted vs encoded/ae: p=0.0005  ✓ significant
  handcrafted vs best_bidask: p=0.0745  ✗ not significant
  encoded/mlp vs encoded/cnn: p=0.0370  ✓ significant
  encoded/mlp vs encoded/ae: p=0.6162  ✗ not significant
  encoded/mlp vs best_bidask: p=0.0566  ✗ not significant
  encoded/cnn vs encoded/ae: p=0.1055  ✗ not significant
  encoded/cnn vs best_bidask: p=0.0032  ✓ significant
  encoded/ae vs best_bidask: p=0.0265  ✓ significant
